Workbook

Sheet Global Air Quality
A1: City | B1: City2 | C1: Country | D1: Date | E1: Date2 | F1: PM2.5 | G1: PM10 | H1: NO2 | I1: SO2 | J1: CO | K1: O3 | L1: Temperature | M1: Humidity | N1: Wind Speed
A2: Johannesburg | B2: =PROPER(A2) -> Johannesburg | C2: South Africa | D2: 45203 | E2: =IF(ISNUMBER(D2),D2,IFERROR(DATE(RIGHT(D2,4),LEFT(D2,FIND("-",D2)-1),MID(D2,FIND("-",D2)+1,FIND("-",D2,4)-FIND("-",D2)-1)),D2)) -> 45203 | F2: 127.51 | G2: 175.1 | I2: 13.02 | J2: 1.7 | K2: 196.41 | L2: 27.46 | M2: 51.14 | N2: 10.26
A3: Istanbul | B3: =PROPER(A3) -> Istanbul | C3: Turkey | D3: 4-22-2023 | E3: =IF(ISNUMBER(D3),D3,IFERROR(DATE(RIGHT(D3,4),LEFT(D3,FIND("-",D3)-1),MID(D3,FIND("-",D3)+1,FIND("-",D3,4)-FIND("-",D3)-1)),D3)) -> 45038 | F3: 93.84 | G3: 34.19 | H3: 79.49 | I3: 44.54 | J3: 5.18 | K3: 183.62 | L3: 10.58 | M3: 30.48 | N3: 14.45
A4: Berlin | B4: =PROPER(A4) -> Berlin | C4: Germany | D4: 10-27-2023 | E4: =IF(ISNUMBER(D4),D4,IFERROR(DATE(RIGHT(D4,4),LEFT(D4,FIND("-",D4)-1),MID(D4,FIND("-",D4)+1,FIND("-",D4,4)-FIND("-",D4)-1)),D4)) -> 45226 | F4: 52.03 | G4: 181.8 | H4: 45.05 | I4: 30.12 | J4: 0.96 | K4: 155.61 | L4: -4.09 | M4: 96.9 | N4: 2.49
A5: SYDNEY | B5: =PROPER(A5) -> Sydney | C5: Australia | D5: 45205 | E5: =IF(ISNUMBER(D5),D5,IFERROR(DATE(RIGHT(D5,4),LEFT(D5,FIND("-",D5)-1),MID(D5,FIND("-",D5)+1,FIND("-",D5,4)-FIND("-",D5)-1)),D5)) -> 45205 | F5: 110.3 | H5: 77.44 | I5: 9.78 | J5: 6.54 | K5: 18.98 | L5: 17.41 | M5: 64.79 | N5: 12.77
A6: Dubai | B6: =PROPER(A6) -> Dubai | C6: United Arab Emirates | D6: 7-23-2023 | E6: =IF(ISNUMBER(D6),D6,IFERROR(DATE(RIGHT(D6,4),LEFT(D6,FIND("-",D6)-1),MID(D6,FIND("-",D6)+1,FIND("-",D6,4)-FIND("-",D6)-1)),D6)) -> 45130 | F6: 120.24 | G6: 48.98 | H6: 98.82 | I6: 6.27 | J6: 6.98 | K6: 133.94 | L6: 13.11 | M6: 31.61 | N6: 5
A7: Johannesburg | B7: =PROPER(A7) -> Johannesburg | C7: South Africa | D7: 7-25-2023 | E7: =IF(ISNUMBER(D7),D7,IFERROR(DATE(RIGHT(D7,4),LEFT(D7,FIND("-",D7)-1),MID(D7,FIND("-",D7)+1,FIND("-",D7,4)-FIND("-",D7)-1)),D7)) -> 45132 | F7: 119.39 | G7: 148.61 | H7: 38.32 | I7: 21.48 | J7: 1.79 | K7: 96.78 | L7: -2.62 | M7: 89.28 | N7: 9.27
A8: Los Angeles | B8: =PROPER(A8) -> Los Angeles | C8: United States Of America | D8: 4-24-2023 | E8: =IF(ISNUMBER(D8),D8,IFERROR(DATE(RIGHT(D8,4),LEFT(D8,FIND("-",D8)-1),MID(D8,FIND("-",D8)+1,FIND("-",D8,4)-FIND("-",D8)-1)),D8)) -> 45040 | H8: 97.71 | I8: 11.14 | J8: 5.82 | K8: 194.72 | L8: 27.69 | M8: 10.62 | N8: 7.55
A9: Mumbai | B9: =PROPER(A9) -> Mumbai | C9: India | D9: 45262 | E9: =IF(ISNUMBER(D9),D9,IFERROR(DATE(RIGHT(D9,4),LEFT(D9,FIND("-",D9)-1),MID(D9,FIND("-",D9)+1,FIND("-",D9,4)-FIND("-",D9)-1)),D9)) -> 45262 | F9: 24.74 | G9: 118.36 | H9: 74.05 | I9: 10.81 | J9: 0.7 | K9: 188.08 | L9: 19.58 | M9: 67.09 | N9: 8.58
A10: Beijing | B10: =PROPER(A10) -> Beijing | C10: China | D10: 45110 | E10: =IF(ISNUMBER(D10),D10,IFERROR(DATE(RIGHT(D10,4),LEFT(D10,FIND("-",D10)-1),MID(D10,FIND("-",D10)+1,FIND("-",D10,4)-FIND("-",D10)-1)),D10)) -> 45110 | F10: 100.19 | G10: 10.16 | H10: 74.82 | I10: 39.88 | J10: 6.81 | K10: 176.9 | L10: 32.85 | M10: 17.65 | N10: 9.53
A11: Johannesburg | B11: =PROPER(A11) -> Johannesburg | C11: South Africa | D11: 5-18-2023 | E11: =IF(ISNUMBER(D11),D11,IFERROR(DATE(RIGHT(D11,4),LEFT(D11,FIND("-",D11)-1),MID(D11,FIND("-",D11)+1,FIND("-",D11,4)-FIND("-",D11)-1)),D11)) -> 45064 | F11: 80.94 | G11: 13.09 | H11: 63.86 | I11: 15.58 | J11: 4.52 | K11: 168.04 | L11: 39.59 | M11: 86.25 | N11: 16.46
A12: Los Angeles | B12: =PROPER(A12) -> Los Angeles | C12: United States Of America | D12: 12-13-2023 | E12: =IF(ISNUMBER(D12),D12,IFERROR(DATE(RIGHT(D12,4),LEFT(D12,FIND("-",D12)-1),MID(D12,FIND("-",D12)+1,FIND("-",D12,4)-FIND("-",D12)-1)),D12)) -> 45273 | F12: 67.85 | G12: 108.38 | H12: 67.98 | I12: 32.69 | J12: 5.95 | K12: 170.87 | L12: 16.12 | M12: 40.58 | N12: 18.13
A13: Johannesburg | B13: =PROPER(A13) -> Johannesburg | C13: South Africa | D13: 11-15-2023 | E13: =IF(ISNUMBER(D13),D13,IFERROR(DATE(RIGHT(D13,4),LEFT(D13,FIND("-",D13)-1),MID(D13,FIND("-",D13)+1,FIND("-",D13,4)-FIND("-",D13)-1)),D13)) -> 45245 | F13: 99.36 | G13: 154.53 | H13: 82.78 | I13: 49.93 | J13: 0.49 | L13: 39.61 | M13: 40.87 | N13: 12.49
A14: Paris | B14: =PROPER(A14) -> Paris | C14: France | D14: 8-16-2023 | E14: =IF(ISNUMBER(D14),D14,IFERROR(DATE(RIGHT(D14,4),LEFT(D14,FIND("-",D14)-1),MID(D14,FIND("-",D14)+1,FIND("-",D14,4)-FIND("-",D14)-1)),D14)) -> 45154 | F14: 19.06 | H14: 46.89 | J14: 1.92 | K14: 129.03 | L14: 23.41 | M14: 93.31 | N14: 17.85
A15: New York | B15: =PROPER(A15) -> New York | C15: United States Of America | D15: 1-28-2023 | E15: =IF(ISNUMBER(D15),D15,IFERROR(DATE(RIGHT(D15,4),LEFT(D15,FIND("-",D15)-1),MID(D15,FIND("-",D15)+1,FIND("-",D15,4)-FIND("-",D15)-1)),D15)) -> 44954 | F15: 37.32 | G15: 137.91 | H15: 70.67 | I15: 1.04 | J15: 2.87 | K15: 54.77 | L15: 31.16 | M15: 75.64 | N15: 1.24
A16: London | B16: =PROPER(A16) -> London | C16: United Kingdom | D16: 3-23-2023 | E16: =IF(ISNUMBER(D16),D16,IFERROR(DATE(RIGHT(D16,4),LEFT(D16,FIND("-",D16)-1),MID(D16,FIND("-",D16)+1,FIND("-",D16,4)-FIND("-",D16)-1)),D16)) -> 45008 | F16: 21.33 | G16: 190.16 | H16: 26.62 | I16: 40.19 | J16: 2.63 | K16: 14.07 | L16: -8.78 | M16: 44.95 | N16: 2.39
A17: Seoul | B17: =PROPER(A17) -> Seoul | C17: South Korea | D17: 45052 | E17: =IF(ISNUMBER(D17),D17,IFERROR(DATE(RIGHT(D17,4),LEFT(D17,FIND("-",D17)-1),MID(D17,FIND("-",D17)+1,FIND("-",D17,4)-FIND("-",D17)-1)),D17)) -> 45052 | F17: 79.71 | G17: 195.27 | H17: 91.26 | J17: 1.24 | L17: -6.26 | M17: 58 | N17: 1.09
A18: Toronto | B18: =PROPER(A18) -> Toronto | C18: Canada | D18: 44932 | E18: =IF(ISNUMBER(D18),D18,IFERROR(DATE(RIGHT(D18,4),LEFT(D18,FIND("-",D18)-1),MID(D18,FIND("-",D18)+1,FIND("-",D18,4)-FIND("-",D18)-1)),D18)) -> 44932 | F18: 111.9 | G18: 117.86 | H18: 60.31 | I18: 10.03 | J18: 2.13 | L18: 35.09 | M18: 16.04 | N18: 19.73
A19: Beijing | B19: =PROPER(A19) -> Beijing | C19: China | D19: 44989 | E19: =IF(ISNUMBER(D19),D19,IFERROR(DATE(RIGHT(D19,4),LEFT(D19,FIND("-",D19)-1),MID(D19,FIND("-",D19)+1,FIND("-",D19,4)-FIND("-",D19)-1)),D19)) -> 44989 | F19: 105.58 | G19: 148.88 | H19: 95.05 | I19: 39.39 | J19: 2.38 | K19: 170.41 | L19: -5.82 | M19: 29.38 | N19: 13.34
A20: New York | B20: =PROPER(A20) -> New York | C20: United States Of America | D20: 7-24-2023 | E20: =IF(ISNUMBER(D20),D20,IFERROR(DATE(RIGHT(D20,4),LEFT(D20,FIND("-",D20)-1),MID(D20,FIND("-",D20)+1,FIND("-",D20,4)-FIND("-",D20)-1)),D20)) -> 45131 | F20: 10.67 | G20: 80.75 | H20: 48.55 | I20: 22.89 | J20: 5.49 | K20: 165.33 | L20: 17.85 | M20: 44.37 | N20: 4.8
A21: Tokyo | B21: =PROPER(A21) -> Tokyo | C21: Japan | D21: 11-28-2023 | E21: =IF(ISNUMBER(D21),D21,IFERROR(DATE(RIGHT(D21,4),LEFT(D21,FIND("-",D21)-1),MID(D21,FIND("-",D21)+1,FIND("-",D21,4)-FIND("-",D21)-1)),D21)) -> 45258 | F21: 127.93 | G21: 83.61 | H21: 61.25 | I21: 33.36 | J21: 6.32 | K21: 24.78 | L21: -7.57 | M21: 13.74 | N21: 9.16
A22: london | B22: =PROPER(A22) -> London | C22: United Kingdom | D22: 10-20-2023 | E22: =IF(ISNUMBER(D22),D22,IFERROR(DATE(RIGHT(D22,4),LEFT(D22,FIND("-",D22)-1),MID(D22,FIND("-",D22)+1,FIND("-",D22,4)-FIND("-",D22)-1)),D22)) -> 45219 | F22: 130.94 | G22: 119.31 | H22: 18.4 | I22: 18.21 | J22: 5.94 | K22: 164.46 | L22: 31.36 | M22: 62.94 | N22: 10.5
A23: Mumbai | B23: =PROPER(A23) -> Mumbai | C23: India | D23: 11-13-2023 | E23: =IF(ISNUMBER(D23),D23,IFERROR(DATE(RIGHT(D23,4),LEFT(D23,FIND("-",D23)-1),MID(D23,FIND("-",D23)+1,FIND("-",D23,4)-FIND("-",D23)-1)),D23)) -> 45243 | F23: 50.27 | G23: 114.71 | H23: 60.56 | I23: 21.8 | K23: 58.38 | L23: 37.23 | M23: 32.97 | N23: 6.56
A24: Dubai | B24: =PROPER(A24) -> Dubai | C24: United Arab Emirates | D24: 11-19-2023 | E24: =IF(ISNUMBER(D24),D24,IFERROR(DATE(RIGHT(D24,4),LEFT(D24,FIND("-",D24)-1),MID(D24,FIND("-",D24)+1,FIND("-",D24,4)-FIND("-",D24)-1)),D24)) -> 45249 | F24: 58.79 | G24: 70.91 | H24: 62.43 | I24: 3.03 | J24: 2.69 | K24: 170.09 | L24: 22.42 | M24: 92.3 | N24: 13.92
A25: Mexico City | B25: =PROPER(A25) -> Mexico City | C25: Mexico | D25: 9-25-2023 | E25: =IF(ISNUMBER(D25),D25,IFERROR(DATE(RIGHT(D25,4),LEFT(D25,FIND("-",D25)-1),MID(D25,FIND("-",D25)+1,FIND("-",D25,4)-FIND("-",D25)-1)),D25)) -> 45194 | F25: 61.98 | G25: 57.84 | H25: 56.01 | J25: 4.83 | K25: 23.04 | L25: 23.47 | M25: 97.29 | N25: 5.97
A26: Madrid | B26: =PROPER(A26) -> Madrid | C26: Spain | D26: 44930 | E26: =IF(ISNUMBER(D26),D26,IFERROR(DATE(RIGHT(D26,4),LEFT(D26,FIND("-",D26)-1),MID(D26,FIND("-",D26)+1,FIND("-",D26,4)-FIND("-",D26)-1)),D26)) -> 44930 | F26: 6.29 | G26: 167.41 | H26: 71.93 | I26: 17.52 | J26: 3.31 | K26: 153.19 | L26: 22.29 | M26: 37.78 | N26: 8.72
A27: London | B27: =PROPER(A27) -> London | C27: United Kingdom | D27: 2-17-2023 | E27: =IF(ISNUMBER(D27),D27,IFERROR(DATE(RIGHT(D27,4),LEFT(D27,FIND("-",D27)-1),MID(D27,FIND("-",D27)+1,FIND("-",D27,4)-FIND("-",D27)-1)),D27)) -> 44974 | F27: 143.09 | G27: 175.85 | H27: 44.14 | I27: 20.59 | J27: 3.92 | K27: 160.2 | L27: -0.47 | M27: 66.37 | N27: 1.31
A28: Mexico City | B28: =PROPER(A28) -> Mexico City | C28: Mexico | D28: 8-16-2023 | E28: =IF(ISNUMBER(D28),D28,IFERROR(DATE(RIGHT(D28,4),LEFT(D28,FIND("-",D28)-1),MID(D28,FIND("-",D28)+1,FIND("-",D28,4)-FIND("-",D28)-1)),D28)) -> 45154 | F28: 81.14 | G28: 123.56 | H28: 9.52 | I28: 47.7 | J28: 8.85 | K28: 23.4 | L28: -5.7 | M28: 49.84 | N28: 18.74
A29: Seoul | B29: =PROPER(A29) -> Seoul | C29: South Korea | D29: 11-27-2023 | E29: =IF(ISNUMBER(D29),D29,IFERROR(DATE(RIGHT(D29,4),LEFT(D29,FIND("-",D29)-1),MID(D29,FIND("-",D29)+1,FIND("-",D29,4)-FIND("-",D29)-1)),D29)) -> 45257 | F29: 73.75 | G29: 150.03 | H29: 42.02 | I29: 11.94 | J29: 0.66 | K29: 140.46 | L29: 4.31 | M29: 80.31 | N29: 6.38
A30: Dubai | B30: =PROPER(A30) -> Dubai | C30: United Arab Emirates | D30: 6-22-2023 | E30: =IF(ISNUMBER(D30),D30,IFERROR(DATE(RIGHT(D30,4),LEFT(D30,FIND("-",D30)-1),MID(D30,FIND("-",D30)+1,FIND("-",D30,4)-FIND("-",D30)-1)),D30)) -> 45099 | F30: 143.31 | G30: 71.65 | H30: 52.05 | I30: 12.39 | J30: 2.19 | K30: 84.33 | L30: 17.24 | M30: 37.78 | N30: 5.64
A31: Bangkok | B31: =PROPER(A31) -> Bangkok | C31: Thailand | D31: 45173 | E31: =IF(ISNUMBER(D31),D31,IFERROR(DATE(RIGHT(D31,4),LEFT(D31,FIND("-",D31)-1),MID(D31,FIND("-",D31)+1,FIND("-",D31,4)-FIND("-",D31)-1)),D31)) -> 45173 | F31: 106.95 | G31: 72.95 | H31: 76.9 | I31: 3.49 | J31: 5.48 | K31: 97.76 | L31: 9.59 | M31: 60.62 | N31: 4.54
A32: New York | B32: =PROPER(A32) -> New York | C32: United States Of America | D32: 45233 | E32: =IF(ISNUMBER(D32),D32,IFERROR(DATE(RIGHT(D32,4),LEFT(D32,FIND("-",D32)-1),MID(D32,FIND("-",D32)+1,FIND("-",D32,4)-FIND("-",D32)-1)),D32)) -> 45233 | F32: 71.19 | G32: 152.28 | H32: 59.61 | I32: 38.15 | J32: 8.53 | K32: 95.3 | L32: 33.59 | M32: 43.37 | N32: 13.96
A33: Seoul | B33: =PROPER(A33) -> Seoul | C33: South Korea | D33: 44930 | E33: =IF(ISNUMBER(D33),D33,IFERROR(DATE(RIGHT(D33,4),LEFT(D33,FIND("-",D33)-1),MID(D33,FIND("-",D33)+1,FIND("-",D33,4)-FIND("-",D33)-1)),D33)) -> 44930 | F33: 69.18 | G33: 89.9 | H33: 15.86 | I33: 8.87 | J33: 4.27 | K33: 118.62 | L33: 38.7 | M33: 89.05 | N33: 16.25
A34: New York | B34: =PROPER(A34) -> New York | C34: United States Of America | D34: 1-21-2023 | E34: =IF(ISNUMBER(D34),D34,IFERROR(DATE(RIGHT(D34,4),LEFT(D34,FIND("-",D34)-1),MID(D34,FIND("-",D34)+1,FIND("-",D34,4)-FIND("-",D34)-1)),D34)) -> 44947 | F34: 30.39 | G34: 108.6 | H34: 97.68 | I34: 43.74 | J34: 7.65 | K34: 127.1 | L34: 18.43 | M34: 51.94 | N34: 13.32
A35: Seoul | B35: =PROPER(A35) -> Seoul | C35: South Korea | D35: 45049 | E35: =IF(ISNUMBER(D35),D35,IFERROR(DATE(RIGHT(D35,4),LEFT(D35,FIND("-",D35)-1),MID(D35,FIND("-",D35)+1,FIND("-",D35,4)-FIND("-",D35)-1)),D35)) -> 45049 | F35: 6.88 | H35: 77.45 | I35: 34.28 | J35: 4.17 | K35: 164.56 | L35: 5.68 | M35: 36.7 | N35: 16.35
A36: Madrid | B36: =PROPER(A36) -> Madrid | C36: Spain | D36: 5-14-2023 | E36: =IF(ISNUMBER(D36),D36,IFERROR(DATE(RIGHT(D36,4),LEFT(D36,FIND("-",D36)-1),MID(D36,FIND("-",D36)+1,FIND("-",D36,4)-FIND("-",D36)-1)),D36)) -> 45060 | F36: 108.72 | G36: 141.27 | H36: 62.22 | I36: 38.76 | J36: 7.83 | K36: 92.5 | L36: -2.17 | M36: 62.51 | N36: 12.8
A37: Rio de Janeiro | B37: =PROPER(A37) -> Rio De Janeiro | C37: Brazil | D37: 1-18-2023 | E37: =IF(ISNUMBER(D37),D37,IFERROR(DATE(RIGHT(D37,4),LEFT(D37,FIND("-",D37)-1),MID(D37,FIND("-",D37)+1,FIND("-",D37,4)-FIND("-",D37)-1)),D37)) -> 44944 | F37: 136.26 | G37: 179.46 | I37: 2.91 | J37: 8.01 | K37: 119.83 | L37: 31.65 | M37: 97.2 | N37: 18.17
A38: London | B38: =PROPER(A38) -> London | C38: United Kingdom | D38: 9-27-2023 | E38: =IF(ISNUMBER(D38),D38,IFERROR(DATE(RIGHT(D38,4),LEFT(D38,FIND("-",D38)-1),MID(D38,FIND("-",D38)+1,FIND("-",D38,4)-FIND("-",D38)-1)),D38)) -> 45196 | F38: 88.31 | G38: 93.23 | H38: 94.67 | I38: 43.87 | J38: 7.85 | K38: 18.6 | L38: 31.95 | M38: 78.56 | N38: 15.72
A39: Berlin | B39: =PROPER(A39) -> Berlin | C39: Germany | D39: 45144 | E39: =IF(ISNUMBER(D39),D39,IFERROR(DATE(RIGHT(D39,4),LEFT(D39,FIND("-",D39)-1),MID(D39,FIND("-",D39)+1,FIND("-",D39,4)-FIND("-",D39)-1)),D39)) -> 45144 | F39: 10.38 | G39: 152.92 | H39: 84.76 | I39: 18.13 | J39: 5.9 | K39: 190.54 | L39: 14.06 | M39: 67.59 | N39: 18.42
A40: MOSCOW | B40: =PROPER(A40) -> Moscow | C40: Russia | D40: 45149 | E40: =IF(ISNUMBER(D40),D40,IFERROR(DATE(RIGHT(D40,4),LEFT(D40,FIND("-",D40)-1),MID(D40,FIND("-",D40)+1,FIND("-",D40,4)-FIND("-",D40)-1)),D40)) -> 45149 | F40: 49.5 | G40: 163.97 | H40: 14.81 | I40: 11.29 | J40: 7.06 | K40: 120.24 | L40: 1.01 | M40: 89.92 | N40: 6.71
...

Sheet Table1
A1: City1 | B1: City | C1: Country | D1: Date1 | E1: Date | F1: PM2.5 | G1: PM10 | H1: NO2 | I1: SO2 | J1: CO | K1: O3 | L1: Temperature | M1: Humidity | N1: Wind Speed
A2: Johannesburg | B2: Johannesburg | C2: South Africa | D2: 45203 | E2: 45203 | F2: 128 | G2: 175 | H2: 30 | I2: 13 | J2: 2 | K2: 196 | L2: 27 | M2: 51 | N2: 10
A3: Istanbul | B3: Istanbul | C3: Turkey | D3: 4-22-2023 | E3: 45038 | F3: 94 | G3: 34 | H3: 79 | I3: 45 | J3: 5 | K3: 184 | L3: 11 | M3: 30 | N3: 14
A4: Berlin | B4: Berlin | C4: Germany | D4: 10-27-2023 | E4: 45226 | F4: 52 | G4: 182 | H4: 45 | I4: 30 | J4: 1 | K4: 156 | L4: -4 | M4: 97 | N4: 2
A5: SYDNEY | B5: Sydney | C5: Australia | D5: 45205 | E5: 45205 | F5: 110 | G5: 82 | H5: 77 | I5: 10 | J5: 7 | K5: 19 | L5: 17 | M5: 65 | N5: 13
A6: Dubai | B6: Dubai | C6: United Arab Emirates | D6: 7-23-2023 | E6: 45130 | F6: 120 | G6: 49 | H6: 99 | I6: 6 | J6: 7 | K6: 134 | L6: 13 | M6: 32 | N6: 5
A7: Johannesburg | B7: Johannesburg | C7: South Africa | D7: 7-25-2023 | E7: 45132 | F7: 119 | G7: 149 | H7: 38 | I7: 21 | J7: 2 | K7: 97 | L7: -3 | M7: 89 | N7: 9
A8: Los Angeles | B8: Los Angeles | C8: United States Of America | D8: 4-24-2023 | E8: 45040 | F8: 15 | G8: 82 | H8: 98 | I8: 11 | J8: 6 | K8: 195 | L8: 28 | M8: 11 | N8: 8
A9: Mumbai | B9: Mumbai | C9: India | D9: 45262 | E9: 45262 | F9: 25 | G9: 118 | H9: 74 | I9: 11 | J9: 1 | K9: 188 | L9: 20 | M9: 67 | N9: 9
A10: Beijing | B10: Beijing | C10: China | D10: 45110 | E10: 45110 | F10: 100 | G10: 10 | H10: 75 | I10: 40 | J10: 7 | K10: 177 | L10: 33 | M10: 18 | N10: 10
A11: Johannesburg | B11: Johannesburg | C11: South Africa | D11: 5-18-2023 | E11: 45064 | F11: 81 | G11: 13 | H11: 64 | I11: 16 | J11: 5 | K11: 168 | L11: 40 | M11: 86 | N11: 16
A12: Los Angeles | B12: Los Angeles | C12: United States Of America | D12: 12-13-2023 | E12: 45273 | F12: 68 | G12: 108 | H12: 68 | I12: 33 | J12: 6 | K12: 171 | L12: 16 | M12: 41 | N12: 18
A13: Johannesburg | B13: Johannesburg | C13: South Africa | D13: 11-15-2023 | E13: 45245 | F13: 99 | G13: 155 | H13: 83 | I13: 50 | J13: 0 | K13: 157 | L13: 40 | M13: 41 | N13: 12
A14: Paris | B14: Paris | C14: France | D14: 8-16-2023 | E14: 45154 | F14: 19 | G14: 82 | H14: 47 | I14: 5 | J14: 2 | K14: 129 | L14: 23 | M14: 93 | N14: 18
A15: New York | B15: New York | C15: United States Of America | D15: 1-28-2023 | E15: 44954 | F15: 37 | G15: 138 | H15: 71 | I15: 1 | J15: 3 | K15: 55 | L15: 31 | M15: 76 | N15: 1
A16: London | B16: London | C16: United Kingdom | D16: 3-23-2023 | E16: 45008 | F16: 21 | G16: 190 | H16: 27 | I16: 40 | J16: 3 | K16: 14 | L16: -9 | M16: 45 | N16: 2
A17: Seoul | B17: Seoul | C17: South Korea | D17: 45052 | E17: 45052 | F17: 80 | G17: 195 | H17: 91 | I17: 5 | J17: 1 | K17: 157 | L17: -6 | M17: 58 | N17: 1
A18: Toronto | B18: Toronto | C18: Canada | D18: 44932 | E18: 44932 | F18: 112 | G18: 118 | H18: 60 | I18: 10 | J18: 2 | K18: 157 | L18: 35 | M18: 16 | N18: 20
A19: Beijing | B19: Beijing | C19: China | D19: 44989 | E19: 44989 | F19: 106 | G19: 149 | H19: 95 | I19: 39 | J19: 2 | K19: 170 | L19: -6 | M19: 29 | N19: 13
A20: New York | B20: New York | C20: United States Of America | D20: 7-24-2023 | E20: 45131 | F20: 11 | G20: 81 | H20: 49 | I20: 23 | J20: 5 | K20: 165 | L20: 18 | M20: 44 | N20: 5
A21: Tokyo | B21: Tokyo | C21: Japan | D21: 11-28-2023 | E21: 45258 | F21: 128 | G21: 84 | H21: 61 | I21: 33 | J21: 6 | K21: 25 | L21: -8 | M21: 14 | N21: 9
A22: london | B22: London | C22: United Kingdom | D22: 10-20-2023 | E22: 45219 | F22: 131 | G22: 119 | H22: 18 | I22: 18 | J22: 6 | K22: 164 | L22: 31 | M22: 63 | N22: 10
A23: Mumbai | B23: Mumbai | C23: India | D23: 11-13-2023 | E23: 45243 | F23: 50 | G23: 115 | H23: 61 | I23: 22 | J23: 6 | K23: 58 | L23: 37 | M23: 33 | N23: 7
A24: Dubai | B24: Dubai | C24: United Arab Emirates | D24: 11-19-2023 | E24: 45249 | F24: 59 | G24: 71 | H24: 62 | I24: 3 | J24: 3 | K24: 170 | L24: 22 | M24: 92 | N24: 14
A25: Mexico City | B25: Mexico City | C25: Mexico | D25: 9-25-2023 | E25: 45194 | F25: 62 | G25: 58 | H25: 56 | I25: 5 | J25: 5 | K25: 23 | L25: 23 | M25: 97 | N25: 6
A26: Madrid | B26: Madrid | C26: Spain | D26: 44930 | E26: 44930 | F26: 6 | G26: 167 | H26: 72 | I26: 18 | J26: 3 | K26: 153 | L26: 22 | M26: 38 | N26: 9
A27: London | B27: London | C27: United Kingdom | D27: 2-17-2023 | E27: 44974 | F27: 143 | G27: 176 | H27: 44 | I27: 21 | J27: 4 | K27: 160 | L27: 0 | M27: 66 | N27: 1
A28: Mexico City | B28: Mexico City | C28: Mexico | D28: 8-16-2023 | E28: 45154 | F28: 81 | G28: 124 | H28: 10 | I28: 48 | J28: 9 | K28: 23 | L28: -6 | M28: 50 | N28: 19
A29: Seoul | B29: Seoul | C29: South Korea | D29: 11-27-2023 | E29: 45257 | F29: 74 | G29: 150 | H29: 42 | I29: 12 | J29: 1 | K29: 140 | L29: 4 | M29: 80 | N29: 6
A30: Dubai | B30: Dubai | C30: United Arab Emirates | D30: 6-22-2023 | E30: 45099 | F30: 143 | G30: 72 | H30: 52 | I30: 12 | J30: 2 | K30: 84 | L30: 17 | M30: 38 | N30: 6
A31: Bangkok | B31: Bangkok | C31: Thailand | D31: 45173 | E31: 45173 | F31: 107 | G31: 73 | H31: 77 | I31: 3 | J31: 5 | K31: 98 | L31: 10 | M31: 61 | N31: 5
A32: New York | B32: New York | C32: United States Of America | D32: 45233 | E32: 45233 | F32: 71 | G32: 152 | H32: 60 | I32: 38 | J32: 9 | K32: 95 | L32: 34 | M32: 43 | N32: 14
A33: Seoul | B33: Seoul | C33: South Korea | D33: 44930 | E33: 44930 | F33: 69 | G33: 90 | H33: 16 | I33: 9 | J33: 4 | K33: 119 | L33: 39 | M33: 89 | N33: 16
A34: New York | B34: New York | C34: United States Of America | D34: 1-21-2023 | E34: 44947 | F34: 30 | G34: 109 | H34: 98 | I34: 44 | J34: 8 | K34: 127 | L34: 18 | M34: 52 | N34: 13
A35: Seoul | B35: Seoul | C35: South Korea | D35: 45049 | E35: 45049 | F35: 7 | G35: 82 | H35: 77 | I35: 34 | J35: 4 | K35: 165 | L35: 6 | M35: 37 | N35: 16
A36: Madrid | B36: Madrid | C36: Spain | D36: 5-14-2023 | E36: 45060 | F36: 109 | G36: 141 | H36: 62 | I36: 39 | J36: 8 | K36: 92 | L36: -2 | M36: 63 | N36: 13
A37: Rio de Janeiro | B37: Rio De Janeiro | C37: Brazil | D37: 1-18-2023 | E37: 44944 | F37: 136 | G37: 179 | H37: 30 | I37: 3 | J37: 8 | K37: 120 | L37: 32 | M37: 97 | N37: 18
A38: London | B38: London | C38: United Kingdom | D38: 9-27-2023 | E38: 45196 | F38: 88 | G38: 93 | H38: 95 | I38: 44 | J38: 8 | K38: 19 | L38: 32 | M38: 79 | N38: 16
A39: Berlin | B39: Berlin | C39: Germany | D39: 45144 | E39: 45144 | F39: 10 | G39: 153 | H39: 85 | I39: 18 | J39: 6 | K39: 191 | L39: 14 | M39: 68 | N39: 18
A40: MOSCOW | B40: Moscow | C40: Russia | D40: 45149 | E40: 45149 | F40: 50 | G40: 164 | H40: 15 | I40: 11 | J40: 7 | K40: 120 | L40: 1 | M40: 90 | N40: 7
...

Sheet Cleaned Global Air Quality
A1: City | B1: Country | C1: Date | D1: PM2.5 | E1: PM10 | F1: NO2 | G1: SO2 | H1: CO | I1: O3 | J1: Temperature | K1: Humidity | L1: Wind Speed | M1: Region | N1: Temperature Category
A2: Johannesburg | B2: =_xlfn.XLOOKUP(A:A,Table1!B:B,Table1!C:C) -> South Africa | C2: =_xlfn.XLOOKUP(A:A,Table1!B:B,Table1!E:E) -> 45203 | D2: =_xlfn.XLOOKUP(A:A,Table1!B:B,Table1!F:F) -> 128 | E2: =_xlfn.XLOOKUP(A:A,Table1!B:B,Table1!G:G) -> 175 | F2: =_xlfn.XLOOKUP(A:A,Table1!B:B,Table1!H:H) -> 30 | G2: =_xlfn.XLOOKUP(A:A,Table1!B:B,Table1!I:I) -> 13 | H2: =_xlfn.XLOOKUP(A:A,Table1!B:B,Table1!J:J) -> 2 | I2: =_xlfn.XLOOKUP(A:A,Table1!B:B,Table1!K:K) -> 196 | J2: =_xlfn.XLOOKUP(A:A,Table1!B:B,Table1!L:L) -> 27 | K2: =_xlfn.XLOOKUP(A:A,Table1!B:B,Table1!M:M) -> 51 | L2: =_xlfn.XLOOKUP(A:A,Table1!B:B,Table1!N:N) -> 10 | M2: {=_xlfn.IFS( OR(B2="India",B2="Thailand",B2="United Arab Emirates",B2="Japan",B2="South Korea",B2="China"),"Asia", OR(B2="Russia",B2="Germany",B2="France",B2="Spain",B2="Turkey",B2="United Kingdom"),"Europe", OR(B2="United States Of America",B2="Canada",B2="Mexico",B2="Brazil"),"America", OR(B2="Egypt",B2="South Africa"),"Africa", B2="Australia","Oceania", TRUE,"Others" )} -> Africa | N2: =IF(J2<=15,"Low",IF(J2<=25,"Moderate","High")) -> High
A3: Istanbul | B3: =_xlfn.XLOOKUP(A:A,Table1!B:B,Table1!C:C) -> Turkey | C3: =_xlfn.XLOOKUP(A:A,Table1!B:B,Table1!E:E) -> 45038 | D3: =_xlfn.XLOOKUP(A:A,Table1!B:B,Table1!F:F) -> 94 | E3: =_xlfn.XLOOKUP(A:A,Table1!B:B,Table1!G:G) -> 34 | F3: =_xlfn.XLOOKUP(A:A,Table1!B:B,Table1!H:H) -> 79 | G3: =_xlfn.XLOOKUP(A:A,Table1!B:B,Table1!I:I) -> 45 | H3: =_xlfn.XLOOKUP(A:A,Table1!B:B,Table1!J:J) -> 5 | I3: =_xlfn.XLOOKUP(A:A,Table1!B:B,Table1!K:K) -> 184 | J3: =_xlfn.XLOOKUP(A:A,Table1!B:B,Table1!L:L) -> 11 | K3: =_xlfn.XLOOKUP(A:A,Table1!B:B,Table1!M:M) -> 30 | L3: =_xlfn.XLOOKUP(A:A,Table1!B:B,Table1!N:N) -> 14 | M3: {=_xlfn.IFS( OR(B3="India",B3="Thailand",B3="United Arab Emirates",B3="Japan",B3="South Korea",B3="China"),"Asia", OR(B3="Russia",B3="Germany",B3="France",B3="Spain",B3="Turkey",B3="United Kingdom"),"Europe", OR(B3="United States Of America",B3="Canada",B3="Mexico",B3="Brazil"),"America", OR(B3="Egypt",B3="South Africa"),"Africa", B3="Australia","Oceania", TRUE,"Others" )} -> Europe | N3: =IF(J3<=15,"Low",IF(J3<=25,"Moderate","High")) -> Low
A4: Berlin | B4: =_xlfn.XLOOKUP(A:A,Table1!B:B,Table1!C:C) -> Germany | C4: =_xlfn.XLOOKUP(A:A,Table1!B:B,Table1!E:E) -> 45226 | D4: =_xlfn.XLOOKUP(A:A,Table1!B:B,Table1!F:F) -> 52 | E4: =_xlfn.XLOOKUP(A:A,Table1!B:B,Table1!G:G) -> 182 | F4: =_xlfn.XLOOKUP(A:A,Table1!B:B,Table1!H:H) -> 45 | G4: =_xlfn.XLOOKUP(A:A,Table1!B:B,Table1!I:I) -> 30 | H4: =_xlfn.XLOOKUP(A:A,Table1!B:B,Table1!J:J) -> 1 | I4: =_xlfn.XLOOKUP(A:A,Table1!B:B,Table1!K:K) -> 156 | J4: =_xlfn.XLOOKUP(A:A,Table1!B:B,Table1!L:L) -> -4 | K4: =_xlfn.XLOOKUP(A:A,Table1!B:B,Table1!M:M) -> 97 | L4: =_xlfn.XLOOKUP(A:A,Table1!B:B,Table1!N:N) -> 2 | M4: {=_xlfn.IFS( OR(B4="India",B4="Thailand",B4="United Arab Emirates",B4="Japan",B4="South Korea",B4="China"),"Asia", OR(B4="Russia",B4="Germany",B4="France",B4="Spain",B4="Turkey",B4="United Kingdom"),"Europe", OR(B4="United States Of America",B4="Canada",B4="Mexico",B4="Brazil"),"America", OR(B4="Egypt",B4="South Africa"),"Africa", B4="Australia","Oceania", TRUE,"Others" )} -> Europe | N4: =IF(J4<=15,"Low",IF(J4<=25,"Moderate","High")) -> Low
A5: Sydney | B5: =_xlfn.XLOOKUP(A:A,Table1!B:B,Table1!C:C) -> Australia | C5: =_xlfn.XLOOKUP(A:A,Table1!B:B,Table1!E:E) -> 45205 | D5: =_xlfn.XLOOKUP(A:A,Table1!B:B,Table1!F:F) -> 110 | E5: =_xlfn.XLOOKUP(A:A,Table1!B:B,Table1!G:G) -> 82 | F5: =_xlfn.XLOOKUP(A:A,Table1!B:B,Table1!H:H) -> 77 | G5: =_xlfn.XLOOKUP(A:A,Table1!B:B,Table1!I:I) -> 10 | H5: =_xlfn.XLOOKUP(A:A,Table1!B:B,Table1!J:J) -> 7 | I5: =_xlfn.XLOOKUP(A:A,Table1!B:B,Table1!K:K) -> 19 | J5: =_xlfn.XLOOKUP(A:A,Table1!B:B,Table1!L:L) -> 17 | K5: =_xlfn.XLOOKUP(A:A,Table1!B:B,Table1!M:M) -> 65 | L5: =_xlfn.XLOOKUP(A:A,Table1!B:B,Table1!N:N) -> 13 | M5: {=_xlfn.IFS( OR(B5="India",B5="Thailand",B5="United Arab Emirates",B5="Japan",B5="South Korea",B5="China"),"Asia", OR(B5="Russia",B5="Germany",B5="France",B5="Spain",B5="Turkey",B5="United Kingdom"),"Europe", OR(B5="United States Of America",B5="Canada",B5="Mexico",B5="Brazil"),"America", OR(B5="Egypt",B5="South Africa"),"Africa", B5="Australia","Oceania", TRUE,"Others" )} -> Oceania | N5: =IF(J5<=15,"Low",IF(J5<=25,"Moderate","High")) -> Moderate
A6: Dubai | B6: =_xlfn.XLOOKUP(A:A,Table1!B:B,Table1!C:C) -> United Arab Emirates | C6: =_xlfn.XLOOKUP(A:A,Table1!B:B,Table1!E:E) -> 45130 | D6: =_xlfn.XLOOKUP(A:A,Table1!B:B,Table1!F:F) -> 120 | E6: =_xlfn.XLOOKUP(A:A,Table1!B:B,Table1!G:G) -> 49 | F6: =_xlfn.XLOOKUP(A:A,Table1!B:B,Table1!H:H) -> 99 | G6: =_xlfn.XLOOKUP(A:A,Table1!B:B,Table1!I:I) -> 6 | H6: =_xlfn.XLOOKUP(A:A,Table1!B:B,Table1!J:J) -> 7 | I6: =_xlfn.XLOOKUP(A:A,Table1!B:B,Table1!K:K) -> 134 | J6: =_xlfn.XLOOKUP(A:A,Table1!B:B,Table1!L:L) -> 13 | K6: =_xlfn.XLOOKUP(A:A,Table1!B:B,Table1!M:M) -> 32 | L6: =_xlfn.XLOOKUP(A:A,Table1!B:B,Table1!N:N) -> 5 | M6: {=_xlfn.IFS( OR(B6="India",B6="Thailand",B6="United Arab Emirates",B6="Japan",B6="South Korea",B6="China"),"Asia", OR(B6="Russia",B6="Germany",B6="France",B6="Spain",B6="Turkey",B6="United Kingdom"),"Europe", OR(B6="United States Of America",B6="Canada",B6="Mexico",B6="Brazil"),"America", OR(B6="Egypt",B6="South Africa"),"Africa", B6="Australia","Oceania", TRUE,"Others" )} -> Asia | N6: =IF(J6<=15,"Low",IF(J6<=25,"Moderate","High")) -> Low
A7: Johannesburg | B7: =_xlfn.XLOOKUP(A:A,Table1!B:B,Table1!C:C) -> South Africa | C7: =_xlfn.XLOOKUP(A:A,Table1!B:B,Table1!E:E) -> 45203 | D7: =_xlfn.XLOOKUP(A:A,Table1!B:B,Table1!F:F) -> 128 | E7: =_xlfn.XLOOKUP(A:A,Table1!B:B,Table1!G:G) -> 175 | F7: =_xlfn.XLOOKUP(A:A,Table1!B:B,Table1!H:H) -> 30 | G7: =_xlfn.XLOOKUP(A:A,Table1!B:B,Table1!I:I) -> 13 | H7: =_xlfn.XLOOKUP(A:A,Table1!B:B,Table1!J:J) -> 2 | I7: =_xlfn.XLOOKUP(A:A,Table1!B:B,Table1!K:K) -> 196 | J7: =_xlfn.XLOOKUP(A:A,Table1!B:B,Table1!L:L) -> 27 | K7: =_xlfn.XLOOKUP(A:A,Table1!B:B,Table1!M:M) -> 51 | L7: =_xlfn.XLOOKUP(A:A,Table1!B:B,Table1!N:N) -> 10 | M7: {=_xlfn.IFS( OR(B7="India",B7="Thailand",B7="United Arab Emirates",B7="Japan",B7="South Korea",B7="China"),"Asia", OR(B7="Russia",B7="Germany",B7="France",B7="Spain",B7="Turkey",B7="United Kingdom"),"Europe", OR(B7="United States Of America",B7="Canada",B7="Mexico",B7="Brazil"),"America", OR(B7="Egypt",B7="South Africa"),"Africa", B7="Australia","Oceania", TRUE,"Others" )} -> Africa | N7: =IF(J7<=15,"Low",IF(J7<=25,"Moderate","High")) -> High
A8: Los Angeles | B8: =_xlfn.XLOOKUP(A:A,Table1!B:B,Table1!C:C) -> United States Of America | C8: =_xlfn.XLOOKUP(A:A,Table1!B:B,Table1!E:E) -> 45040 | D8: =_xlfn.XLOOKUP(A:A,Table1!B:B,Table1!F:F) -> 15 | E8: =_xlfn.XLOOKUP(A:A,Table1!B:B,Table1!G:G) -> 82 | F8: =_xlfn.XLOOKUP(A:A,Table1!B:B,Table1!H:H) -> 98 | G8: =_xlfn.XLOOKUP(A:A,Table1!B:B,Table1!I:I) -> 11 | H8: =_xlfn.XLOOKUP(A:A,Table1!B:B,Table1!J:J) -> 6 | I8: =_xlfn.XLOOKUP(A:A,Table1!B:B,Table1!K:K) -> 195 | J8: =_xlfn.XLOOKUP(A:A,Table1!B:B,Table1!L:L) -> 28 | K8: =_xlfn.XLOOKUP(A:A,Table1!B:B,Table1!M:M) -> 11 | L8: =_xlfn.XLOOKUP(A:A,Table1!B:B,Table1!N:N) -> 8 | M8: {=_xlfn.IFS( OR(B8="India",B8="Thailand",B8="United Arab Emirates",B8="Japan",B8="South Korea",B8="China"),"Asia", OR(B8="Russia",B8="Germany",B8="France",B8="Spain",B8="Turkey",B8="United Kingdom"),"Europe", OR(B8="United States Of America",B8="Canada",B8="Mexico",B8="Brazil"),"America", OR(B8="Egypt",B8="South Africa"),"Africa", B8="Australia","Oceania", TRUE,"Others" )} -> America | N8: =IF(J8<=15,"Low",IF(J8<=25,"Moderate","High")) -> High
A9: Mumbai | B9: =_xlfn.XLOOKUP(A:A,Table1!B:B,Table1!C:C) -> India | C9: =_xlfn.XLOOKUP(A:A,Table1!B:B,Table1!E:E) -> 45262 | D9: =_xlfn.XLOOKUP(A:A,Table1!B:B,Table1!F:F) -> 25 | E9: =_xlfn.XLOOKUP(A:A,Table1!B:B,Table1!G:G) -> 118 | F9: =_xlfn.XLOOKUP(A:A,Table1!B:B,Table1!H:H) -> 74 | G9: =_xlfn.XLOOKUP(A:A,Table1!B:B,Table1!I:I) -> 11 | H9: =_xlfn.XLOOKUP(A:A,Table1!B:B,Table1!J:J) -> 1 | I9: =_xlfn.XLOOKUP(A:A,Table1!B:B,Table1!K:K) -> 188 | J9: =_xlfn.XLOOKUP(A:A,Table1!B:B,Table1!L:L) -> 20 | K9: =_xlfn.XLOOKUP(A:A,Table1!B:B,Table1!M:M) -> 67 | L9: =_xlfn.XLOOKUP(A:A,Table1!B:B,Table1!N:N) -> 9 | M9: {=_xlfn.IFS( OR(B9="India",B9="Thailand",B9="United Arab Emirates",B9="Japan",B9="South Korea",B9="China"),"Asia", OR(B9="Russia",B9="Germany",B9="France",B9="Spain",B9="Turkey",B9="United Kingdom"),"Europe", OR(B9="United States Of America",B9="Canada",B9="Mexico",B9="Brazil"),"America", OR(B9="Egypt",B9="South Africa"),"Africa", B9="Australia","Oceania", TRUE,"Others" )} -> Asia | N9: =IF(J9<=15,"Low",IF(J9<=25,"Moderate","High")) -> Moderate
A10: Beijing | B10: =_xlfn.XLOOKUP(A:A,Table1!B:B,Table1!C:C) -> China | C10: =_xlfn.XLOOKUP(A:A,Table1!B:B,Table1!E:E) -> 45110 | D10: =_xlfn.XLOOKUP(A:A,Table1!B:B,Table1!F:F) -> 100 | E10: =_xlfn.XLOOKUP(A:A,Table1!B:B,Table1!G:G) -> 10 | F10: =_xlfn.XLOOKUP(A:A,Table1!B:B,Table1!H:H) -> 75 | G10: =_xlfn.XLOOKUP(A:A,Table1!B:B,Table1!I:I) -> 40 | H10: =_xlfn.XLOOKUP(A:A,Table1!B:B,Table1!J:J) -> 7 | I10: =_xlfn.XLOOKUP(A:A,Table1!B:B,Table1!K:K) -> 177 | J10: =_xlfn.XLOOKUP(A:A,Table1!B:B,Table1!L:L) -> 33 | K10: =_xlfn.XLOOKUP(A:A,Table1!B:B,Table1!M:M) -> 18 | L10: =_xlfn.XLOOKUP(A:A,Table1!B:B,Table1!N:N) -> 10 | M10: {=_xlfn.IFS( OR(B10="India",B10="Thailand",B10="United Arab Emirates",B10="Japan",B10="South Korea",B10="China"),"Asia", OR(B10="Russia",B10="Germany",B10="France",B10="Spain",B10="Turkey",B10="United Kingdom"),"Europe", OR(B10="United States Of America",B10="Canada",B10="Mexico",B10="Brazil"),"America", OR(B10="Egypt",B10="South Africa"),"Africa", B10="Australia","Oceania", TRUE,"Others" )} -> Asia | N10: =IF(J10<=15,"Low",IF(J10<=25,"Moderate","High")) -> High
A11: Johannesburg | B11: =_xlfn.XLOOKUP(A:A,Table1!B:B,Table1!C:C) -> South Africa | C11: =_xlfn.XLOOKUP(A:A,Table1!B:B,Table1!E:E) -> 45203 | D11: =_xlfn.XLOOKUP(A:A,Table1!B:B,Table1!F:F) -> 128 | E11: =_xlfn.XLOOKUP(A:A,Table1!B:B,Table1!G:G) -> 175 | F11: =_xlfn.XLOOKUP(A:A,Table1!B:B,Table1!H:H) -> 30 | G11: =_xlfn.XLOOKUP(A:A,Table1!B:B,Table1!I:I) -> 13 | H11: =_xlfn.XLOOKUP(A:A,Table1!B:B,Table1!J:J) -> 2 | I11: =_xlfn.XLOOKUP(A:A,Table1!B:B,Table1!K:K) -> 196 | J11: =_xlfn.XLOOKUP(A:A,Table1!B:B,Table1!L:L) -> 27 | K11: =_xlfn.XLOOKUP(A:A,Table1!B:B,Table1!M:M) -> 51 | L11: =_xlfn.XLOOKUP(A:A,Table1!B:B,Table1!N:N) -> 10 | M11: {=_xlfn.IFS( OR(B11="India",B11="Thailand",B11="United Arab Emirates",B11="Japan",B11="South Korea",B11="China"),"Asia", OR(B11="Russia",B11="Germany",B11="France",B11="Spain",B11="Turkey",B11="United Kingdom"),"Europe", OR(B11="United States Of America",B11="Canada",B11="Mexico",B11="Brazil"),"America", OR(B11="Egypt",B11="South Africa"),"Africa", B11="Australia","Oceania", TRUE,"Others" )} -> Africa | N11: =IF(J11<=15,"Low",IF(J11<=25,"Moderate","High")) -> High
A12: Los Angeles | B12: =_xlfn.XLOOKUP(A:A,Table1!B:B,Table1!C:C) -> United States Of America | C12: =_xlfn.XLOOKUP(A:A,Table1!B:B,Table1!E:E) -> 45040 | D12: =_xlfn.XLOOKUP(A:A,Table1!B:B,Table1!F:F) -> 15 | E12: =_xlfn.XLOOKUP(A:A,Table1!B:B,Table1!G:G) -> 82 | F12: =_xlfn.XLOOKUP(A:A,Table1!B:B,Table1!H:H) -> 98 | G12: =_xlfn.XLOOKUP(A:A,Table1!B:B,Table1!I:I) -> 11 | H12: =_xlfn.XLOOKUP(A:A,Table1!B:B,Table1!J:J) -> 6 | I12: =_xlfn.XLOOKUP(A:A,Table1!B:B,Table1!K:K) -> 195 | J12: =_xlfn.XLOOKUP(A:A,Table1!B:B,Table1!L:L) -> 28 | K12: =_xlfn.XLOOKUP(A:A,Table1!B:B,Table1!M:M) -> 11 | L12: =_xlfn.XLOOKUP(A:A,Table1!B:B,Table1!N:N) -> 8 | M12: {=_xlfn.IFS( OR(B12="India",B12="Thailand",B12="United Arab Emirates",B12="Japan",B12="South Korea",B12="China"),"Asia", OR(B12="Russia",B12="Germany",B12="France",B12="Spain",B12="Turkey",B12="United Kingdom"),"Europe", OR(B12="United States Of America",B12="Canada",B12="Mexico",B12="Brazil"),"America", OR(B12="Egypt",B12="South Africa"),"Africa", B12="Australia","Oceania", TRUE,"Others" )} -> America | N12: =IF(J12<=15,"Low",IF(J12<=25,"Moderate","High")) -> High
A13: Johannesburg | B13: =_xlfn.XLOOKUP(A:A,Table1!B:B,Table1!C:C) -> South Africa | C13: =_xlfn.XLOOKUP(A:A,Table1!B:B,Table1!E:E) -> 45203 | D13: =_xlfn.XLOOKUP(A:A,Table1!B:B,Table1!F:F) -> 128 | E13: =_xlfn.XLOOKUP(A:A,Table1!B:B,Table1!G:G) -> 175 | F13: =_xlfn.XLOOKUP(A:A,Table1!B:B,Table1!H:H) -> 30 | G13: =_xlfn.XLOOKUP(A:A,Table1!B:B,Table1!I:I) -> 13 | H13: =_xlfn.XLOOKUP(A:A,Table1!B:B,Table1!J:J) -> 2 | I13: =_xlfn.XLOOKUP(A:A,Table1!B:B,Table1!K:K) -> 196 | J13: =_xlfn.XLOOKUP(A:A,Table1!B:B,Table1!L:L) -> 27 | K13: =_xlfn.XLOOKUP(A:A,Table1!B:B,Table1!M:M) -> 51 | L13: =_xlfn.XLOOKUP(A:A,Table1!B:B,Table1!N:N) -> 10 | M13: {=_xlfn.IFS( OR(B13="India",B13="Thailand",B13="United Arab Emirates",B13="Japan",B13="South Korea",B13="China"),"Asia", OR(B13="Russia",B13="Germany",B13="France",B13="Spain",B13="Turkey",B13="United Kingdom"),"Europe", OR(B13="United States Of America",B13="Canada",B13="Mexico",B13="Brazil"),"America", OR(B13="Egypt",B13="South Africa"),"Africa", B13="Australia","Oceania", TRUE,"Others" )} -> Africa | N13: =IF(J13<=15,"Low",IF(J13<=25,"Moderate","High")) -> High
... A6119: Mexico City | B6119: =_xlfn.XLOOKUP(A:A,Table1!B:B,Table1!C:C) -> Mexico | C6119: =_xlfn.XLOOKUP(A:A,Table1!B:B,Table1!E:E) -> 45063 | D6119: =_xlfn.XLOOKUP(A:A,Table1!B:B,Table1!F:F) -> 10 | E6119: =_xlfn.XLOOKUP(A:A,Table1!B:B,Table1!G:G) -> 39 | F6119: =_xlfn.XLOOKUP(A:A,Table1!B:B,Table1!H:H) -> 36 | G6119: =_xlfn.XLOOKUP(A:A,Table1!B:B,Table1!I:I) -> 3 | H6119: =_xlfn.XLOOKUP(A:A,Table1!B:B,Table1!J:J) -> 1 | I6119: =_xlfn.XLOOKUP(A:A,Table1!B:B,Table1!K:K) -> 79 | J6119: =_xlfn.XLOOKUP(A:A,Table1!B:B,Table1!L:L) -> -8 | K6119: =_xlfn.XLOOKUP(A:A,Table1!B:B,Table1!M:M) -> 45 | L6119: =_xlfn.XLOOKUP(A:A,Table1!B:B,Table1!N:N) -> 19 | M6119: {=_xlfn.IFS( OR(B6119="India",B6119="Thailand",B6119="United Arab Emirates",B6119="Japan",B6119="South Korea",B6119="China"),"Asia", OR(B6119="Russia",B6119="Germany",B6119="France",B6119="Spain",B6119="Turkey",B6119="United Kingdom"),"Europe", OR(B6119="United States Of America",B6119="Canada",B6119="Mexico",B6119="Brazil"),"America", OR(B6119="Egypt",B6119="South Africa"),"Africa", B6119="Australia","Oceania", TRUE,"Others" )} -> America | N6119: =IF(J6119<=15,"Low",IF(J6119<=25,"Moderate","High")) -> Low

Sheet Asia
A1: City | B1: Country | C1: Date | D1: PM2.5 | E1: PM10 | F1: NO2 | G1: SO2 | H1: CO | I1: O3 | J1: Temperature | K1: Humidity | L1: Wind Speed | M1: Region | N1: Temperature Category
A2: Dubai | B2: United Arab Emirates | C2: 45130 | D2: 120 | E2: 49 | F2: 99 | G2: 6 | H2: 7 | I2: 134 | J2: 13 | K2: 32 | L2: 5 | M2: Asia | N2: Low
A3: Mumbai | B3: India | C3: 45262 | D3: 25 | E3: 118 | F3: 74 | G3: 11 | H3: 1 | I3: 188 | J3: 20 | K3: 67 | L3: 9 | M3: Asia | N3: Moderate
A4: Beijing | B4: China | C4: 45110 | D4: 100 | E4: 10 | F4: 75 | G4: 40 | H4: 7 | I4: 177 | J4: 33 | K4: 18 | L4: 10 | M4: Asia | N4: High
A5: Seoul | B5: South Korea | C5: 45052 | D5: 80 | E5: 195 | F5: 91 | G5: 5 | H5: 1 | I5: 157 | J5: -6 | K5: 58 | L5: 1 | M5: Asia | N5: Low
A6: Beijing | B6: China | C6: 45110 | D6: 100 | E6: 10 | F6: 75 | G6: 40 | H6: 7 | I6: 177 | J6: 33 | K6: 18 | L6: 10 | M6: Asia | N6: High
A7: Tokyo | B7: Japan | C7: 45258 | D7: 128 | E7: 84 | F7: 61 | G7: 33 | H7: 6 | I7: 25 | J7: -8 | K7: 14 | L7: 9 | M7: Asia | N7: Low
A8: Mumbai | B8: India | C8: 45262 | D8: 25 | E8: 118 | F8: 74 | G8: 11 | H8: 1 | I8: 188 | J8: 20 | K8: 67 | L8: 9 | M8: Asia | N8: Moderate
A9: Dubai | B9: United Arab Emirates | C9: 45130 | D9: 120 | E9: 49 | F9: 99 | G9: 6 | H9: 7 | I9: 134 | J9: 13 | K9: 32 | L9: 5 | M9: Asia | N9: Low
A10: Seoul | B10: South Korea | C10: 45257 | D10: 74 | E10: 150 | F10: 42 | G10: 12 | H10: 1 | I10: 140 | J10: 4 | K10: 80 | L10: 6 | M10: Asia | N10: Low
A11: Dubai | B11: United Arab Emirates | C11: 45130 | D11: 120 | E11: 49 | F11: 99 | G11: 6 | H11: 7 | I11: 134 | J11: 13 | K11: 32 | L11: 5 | M11: Asia | N11: Low
A12: Bangkok | B12: Thailand | C12: 45173 | D12: 107 | E12: 73 | F12: 77 | G12: 3 | H12: 5 | I12: 98 | J12: 10 | K12: 61 | L12: 5 | M12: Asia | N12: Low
A13: Seoul | B13: South Korea | C13: 45257 | D13: 74 | E13: 150 | F13: 42 | G13: 12 | H13: 1 | I13: 140 | J13: 4 | K13: 80 | L13: 6 | M13: Asia | N13: Low
... A1831: Beijing | B1831: China | C1831: 44950 | D1831: 37 | E1831: 160 | F1831: 75 | G1831: 14 | H1831: 1 | I1831: 194 | J1831: 27 | K1831: 41 | L1831: 20 | M1831: Asia | N1831: High

Sheet Europe
A1: City | B1: Country | C1: Date | D1: PM2.5 | E1: PM10 | F1: NO2 | G1: SO2 | H1: CO | I1: O3 | J1: Temperature | K1: Humidity | L1: Wind Speed | M1: Region | N1: Temperature Category
A2: Istanbul | B2: Turkey | C2: 45038 | D2: 94 | E2: 34 | F2: 79 | G2: 45 | H2: 5 | I2: 184 | J2: 11 | K2: 30 | L2: 14 | M2: Europe | N2: Low
A3: Berlin | B3: Germany | C3: 45226 | D3: 52 | E3: 182 | F3: 45 | G3: 30 | H3: 1 | I3: 156 | J3: -4 | K3: 97 | L3: 2 | M3: Europe | N3: Low
A4: Paris | B4: France | C4: 45154 | D4: 19 | E4: 82 | F4: 47 | G4: 5 | H4: 2 | I4: 129 | J4: 23 | K4: 93 | L4: 18 | M4: Europe | N4: Moderate
A5: London | B5: United Kingdom | C5: 45008 | D5: 21 | E5: 190 | F5: 27 | G5: 40 | H5: 3 | I5: 14 | J5: -9 | K5: 45 | L5: 2 | M5: Europe | N5: Low
A6: London | B6: United Kingdom | C6: 45008 | D6: 21 | E6: 190 | F6: 27 | G6: 40 | H6: 3 | I6: 14 | J6: -9 | K6: 45 | L6: 2 | M6: Europe | N6: Low
A7: Madrid | B7: Spain | C7: 44930 | D7: 6 | E7: 167 | F7: 72 | G7: 18 | H7: 3 | I7: 153 | J7: 22 | K7: 38 | L7: 9 | M7: Europe | N7: Moderate
A8: London | B8: United Kingdom | C8: 45008 | D8: 21 | E8: 190 | F8: 27 | G8: 40 | H8: 3 | I8: 14 | J8: -9 | K8: 45 | L8: 2 | M8: Europe | N8: Low
A9: Madrid | B9: Spain | C9: 44930 | D9: 6 | E9: 167 | F9: 72 | G9: 18 | H9: 3 | I9: 153 | J9: 22 | K9: 38 | L9: 9 | M9: Europe | N9: Moderate
A10: London | B10: United Kingdom | C10: 45008 | D10: 21 | E10: 190 | F10: 27 | G10: 40 | H10: 3 | I10: 14 | J10: -9 | K10: 45 | L10: 2 | M10: Europe | N10: Low
A11: Berlin | B11: Germany | C11: 45226 | D11: 52 | E11: 182 | F11: 45 | G11: 30 | H11: 1 | I11: 156 | J11: -4 | K11: 97 | L11: 2 | M11: Europe | N11: Low
A12: Moscow | B12: Russia | C12: 45149 | D12: 50 | E12: 164 | F12: 15 | G12: 11 | H12: 7 | I12: 120 | J12: 1 | K12: 90 | L12: 7 | M12: Europe | N12: Low
A13: Berlin | B13: Germany | C13: 45226 | D13: 52 | E13: 182 | F13: 45 | G13: 30 | H13: 1 | I13: 156 | J13: -4 | K13: 97 | L13: 2 | M13: Europe | N13: Low
... A1864: Moscow | B1864: Russia | C1864: 45286 | D1864: 133 | E1864: 91 | F1864: 96 | G1864: 39 | H1864: 3 | I1864: 150 | J1864: -7 | K1864: 61 | L1864: 17 | M1864: Europe | N1864: Low

Sheet Africa
A1: City | B1: Country | C1: Date | D1: PM2.5 | E1: PM10 | F1: NO2 | G1: SO2 | H1: CO | I1: O3 | J1: Temperature | K1: Humidity | L1: Wind Speed | M1: Region | N1: Temperature Category
A2: Johannesburg | B2: South Africa | C2: 45203 | D2: 128 | E2: 175 | F2: 30 | G2: 13 | H2: 2 | I2: 196 | J2: 27 | K2: 51 | L2: 10 | M2: Africa | N2: High
A3: Johannesburg | B3: South Africa | C3: 45203 | D3: 128 | E3: 175 | F3: 30 | G3: 13 | H3: 2 | I3: 196 | J3: 27 | K3: 51 | L3: 10 | M3: Africa | N3: High
A4: Johannesburg | B4: South Africa | C4: 45203 | D4: 128 | E4: 175 | F4: 30 | G4: 13 | H4: 2 | I4: 196 | J4: 27 | K4: 51 | L4: 10 | M4: Africa | N4: High
A5: Johannesburg | B5: South Africa | C5: 45203 | D5: 128 | E5: 175 | F5: 30 | G5: 13 | H5: 2 | I5: 196 | J5: 27 | K5: 51 | L5: 10 | M5: Africa | N5: High
A6: Johannesburg | B6: South Africa | C6: 45203 | D6: 128 | E6: 175 | F6: 30 | G6: 13 | H6: 2 | I6: 196 | J6: 27 | K6: 51 | L6: 10 | M6: Africa | N6: High
A7: Johannesburg | B7: South Africa | C7: 45203 | D7: 128 | E7: 175 | F7: 30 | G7: 13 | H7: 2 | I7: 196 | J7: 27 | K7: 51 | L7: 10 | M7: Africa | N7: High
A8: Johannesburg | B8: South Africa | C8: 45203 | D8: 128 | E8: 175 | F8: 30 | G8: 13 | H8: 2 | I8: 196 | J8: 27 | K8: 51 | L8: 10 | M8: Africa | N8: High
A9: Cairo | B9: Egypt | C9: 45041 | D9: 86 | E9: 82 | F9: 84 | G9: 16 | H9: 7 | I9: 186 | J9: 4 | K9: 16 | L9: 5 | M9: Africa | N9: Low
A10: Johannesburg | B10: South Africa | C10: 45203 | D10: 128 | E10: 175 | F10: 30 | G10: 13 | H10: 2 | I10: 196 | J10: 27 | K10: 51 | L10: 10 | M10: Africa | N10: High
A11: Johannesburg | B11: South Africa | C11: 45203 | D11: 128 | E11: 175 | F11: 30 | G11: 13 | H11: 2 | I11: 196 | J11: 27 | K11: 51 | L11: 10 | M11: Africa | N11: High
A12: Cairo | B12: Egypt | C12: 45041 | D12: 86 | E12: 82 | F12: 84 | G12: 16 | H12: 7 | I12: 186 | J12: 4 | K12: 16 | L12: 5 | M12: Africa | N12: Low
A13: Cairo | B13: Egypt | C13: 45041 | D13: 86 | E13: 82 | F13: 84 | G13: 16 | H13: 7 | I13: 186 | J13: 4 | K13: 16 | L13: 5 | M13: Africa | N13: Low
... A629: Johannesburg | B629: South Africa | C629: 45123 | D629: 121 | E629: 200 | F629: 39 | G629: 6 | H629: 7 | I629: 181 | J629: -8 | K629: 17 | L629: 20 | M629: Africa | N629: Low

Sheet America
A1: City | B1: Country | C1: Date | D1: PM2.5 | E1: PM10 | F1: NO2 | G1: SO2 | H1: CO | I1: O3 | J1: Temperature | K1: Humidity | L1: Wind Speed | M1: Region | N1: Temperature Category
A2: Los Angeles | B2: United States Of America | C2: 45040 | D2: 15 | E2: 82 | F2: 98 | G2: 11 | H2: 6 | I2: 195 | J2: 28 | K2: 11 | L2: 8 | M2: America | N2: High
A3: Los Angeles | B3: United States Of America | C3: 45040 | D3: 15 | E3: 82 | F3: 98 | G3: 11 | H3: 6 | I3: 195 | J3: 28 | K3: 11 | L3: 8 | M3: America | N3: High
A4: New York | B4: United States Of America | C4: 44954 | D4: 37 | E4: 138 | F4: 71 | G4: 1 | H4: 3 | I4: 55 | J4: 31 | K4: 76 | L4: 1 | M4: America | N4: High
A5: Toronto | B5: Canada | C5: 44932 | D5: 112 | E5: 118 | F5: 60 | G5: 10 | H5: 2 | I5: 157 | J5: 35 | K5: 16 | L5: 20 | M5: America | N5: High
A6: New York | B6: United States Of America | C6: 44954 | D6: 37 | E6: 138 | F6: 71 | G6: 1 | H6: 3 | I6: 55 | J6: 31 | K6: 76 | L6: 1 | M6: America | N6: High
A7: Mexico City | B7: Mexico | C7: 45194 | D7: 62 | E7: 58 | F7: 56 | G7: 5 | H7: 5 | I7: 23 | J7: 23 | K7: 97 | L7: 6 | M7: America | N7: Moderate
A8: Mexico City | B8: Mexico | C8: 45194 | D8: 62 | E8: 58 | F8: 56 | G8: 5 | H8: 5 | I8: 23 | J8: 23 | K8: 97 | L8: 6 | M8: America | N8: Moderate
A9: New York | B9: United States Of America | C9: 45233 | D9: 71 | E9: 152 | F9: 60 | G9: 38 | H9: 9 | I9: 95 | J9: 34 | K9: 43 | L9: 14 | M9: America | N9: High
A10: New York | B10: United States Of America | C10: 44954 | D10: 37 | E10: 138 | F10: 71 | G10: 1 | H10: 3 | I10: 55 | J10: 31 | K10: 76 | L10: 1 | M10: America | N10: High
A11: Rio De Janeiro | B11: Brazil | C11: 44944 | D11: 136 | E11: 179 | F11: 30 | G11: 3 | H11: 8 | I11: 120 | J11: 32 | K11: 97 | L11: 18 | M11: America | N11: High
A12: Mexico City | B12: Mexico | C12: 45194 | D12: 62 | E12: 58 | F12: 56 | G12: 5 | H12: 5 | I12: 23 | J12: 23 | K12: 97 | L12: 6 | M12: America | N12: Moderate
A13: Rio De Janeiro | B13: Brazil | C13: 44944 | D13: 136 | E13: 179 | F13: 30 | G13: 3 | H13: 8 | I13: 120 | J13: 32 | K13: 97 | L13: 18 | M13: America | N13: High
... A1505: Mexico City | B1505: Mexico | C1505: 45063 | D1505: 10 | E1505: 39 | F1505: 36 | G1505: 3 | H1505: 1 | I1505: 79 | J1505: -8 | K1505: 45 | L1505: 19 | M1505: America | N1505: Low

Sheet Oceania
A1: City | B1: Country | C1: Date | D1: PM2.5 | E1: PM10 | F1: NO2 | G1: SO2 | H1: CO | I1: O3 | J1: Temperature | K1: Humidity | L1: Wind Speed | M1: Region | N1: Temperature Category
A2: Sydney | B2: Australia | C2: 45205 | D2: 110 | E2: 82 | F2: 77 | G2: 10 | H2: 7 | I2: 19 | J2: 17 | K2: 65 | L2: 13 | M2: Oceania | N2: Moderate
A3: Sydney | B3: Australia | C3: 45205 | D3: 110 | E3: 82 | F3: 77 | G3: 10 | H3: 7 | I3: 19 | J3: 17 | K3: 65 | L3: 13 | M3: Oceania | N3: Moderate
A4: Sydney | B4: Australia | C4: 45205 | D4: 110 | E4: 82 | F4: 77 | G4: 10 | H4: 7 | I4: 19 | J4: 17 | K4: 65 | L4: 13 | M4: Oceania | N4: Moderate
A5: Sydney | B5: Australia | C5: 45205 | D5: 110 | E5: 82 | F5: 77 | G5: 10 | H5: 7 | I5: 19 | J5: 17 | K5: 65 | L5: 13 | M5: Oceania | N5: Moderate
A6: Sydney | B6: Australia | C6: 45205 | D6: 110 | E6: 82 | F6: 77 | G6: 10 | H6: 7 | I6: 19 | J6: 17 | K6: 65 | L6: 13 | M6: Oceania | N6: Moderate
A7: Sydney | B7: Australia | C7: 45205 | D7: 110 | E7: 82 | F7: 77 | G7: 10 | H7: 7 | I7: 19 | J7: 17 | K7: 65 | L7: 13 | M7: Oceania | N7: Moderate
A8: Sydney | B8: Australia | C8: 45205 | D8: 110 | E8: 82 | F8: 77 | G8: 10 | H8: 7 | I8: 19 | J8: 17 | K8: 65 | L8: 13 | M8: Oceania | N8: Moderate
A9: Sydney | B9: Australia | C9: 45205 | D9: 110 | E9: 82 | F9: 77 | G9: 10 | H9: 7 | I9: 19 | J9: 17 | K9: 65 | L9: 13 | M9: Oceania | N9: Moderate
A10: Sydney | B10: Australia | C10: 44942 | D10: 132 | E10: 99 | F10: 29 | G10: 9 | H10: 3 | I10: 164 | J10: 29 | K10: 69 | L10: 9 | M10: Oceania | N10: High
A11: Sydney | B11: Australia | C11: 45205 | D11: 110 | E11: 82 | F11: 77 | G11: 10 | H11: 7 | I11: 19 | J11: 17 | K11: 65 | L11: 13 | M11: Oceania | N11: Moderate
A12: Sydney | B12: Australia | C12: 45205 | D12: 110 | E12: 82 | F12: 77 | G12: 10 | H12: 7 | I12: 19 | J12: 17 | K12: 65 | L12: 13 | M12: Oceania | N12: Moderate
A13: Sydney | B13: Australia | C13: 45205 | D13: 110 | E13: 82 | F13: 77 | G13: 10 | H13: 7 | I13: 19 | J13: 17 | K13: 65 | L13: 13 | M13: Oceania | N13: Moderate
... A294: Sydney | B294: Australia | C294: 44942 | D294: 132 | E294: 99 | F294: 29 | G294: 9 | H294: 3 | I294: 164 | J294: 29 | K294: 69 | L294: 9 | M294: Oceania | N294: High
